Workbook

Sheet Uitleg
A1: Hoe gebruik je dit bestand?
A2: Tabblad "Bars": één rij per zichtbare bar (België + Costa Blanca), gesorteerd per regio. Filter bovenaan om bv. alleen Gent te zien.
A3: Kolommen E–F: wat we nu denken. Ja = groen, Nee = grijs, ? = geel (onbekend, zeker even checken).
A4: Kolom G: waarop dat gebaseerd is, en wat je ter plaatse best nakijkt. Kolom H: link naar de bron.
A5: Gele kolommen I–L vul JIJ in als je er bent: datum, je eigen oordeel (keuzelijst Ja/Nee/?) en een opmerking.
A7: Voorbeeld van een ingevulde rij (I–L):
A8: Bezocht op: 12/10/2026 · 💻 Klopt?: Nee · 🚴 Klopt?: Ja · Opmerking: "Geen stopcontacten, wel 2 fietsenrekken voor de deur"
A10: Wat telt als...
A11: 💻 PC-friendly: wifi, stopcontacten, genoeg plaats en laptops toegelaten (minstens op weekdagen).
A12: 🚴 Cycling-friendly: fietsers welkom: fietsenrek of fiets in het zicht, wieler-sfeer of -club, of een vaste stop op populaire fietsroutes.
A14: Klaar? Stuur het bestand terug naar Claude: de verschillen worden dan in één script in de app gezet.

Sheet Bars
A1: Regio | B1: Plaats | C1: Bar | D1: Adres | E1: 💻 PC-friendly | F1: 🚴 Cycling-friendly | G1: Notitie (wat we weten) | H1: Bron | I1: ✔ Bezocht op | J1: 💻 Klopt? (mijn oordeel) | K1: 🚴 Klopt? (mijn oordeel) | L1: Mijn opmerking ter plaatse
A2: Antwerpen | B2: Antwerpen | C2: Andy Roasters | D2: Amerikalei 82 | E2: ? | F2: ? | G2: Geen info over wifi/laptops of fietsen gevonden; retro-interieur, open vanaf 7u30. Ter plaatse: wifi, stopcontacten, fietsenrek. | H2: link
A3: Antwerpen | B3: Antwerpen | C3: Black & Yellow | D3: Nassaustraat 7 | E3: Ja | F3: ? | G3: Gratis wifi, laptop friendly; wo en za gesloten. Ter plaatse: stopcontacten, fietsenrek? | H3: link
A4: Antwerpen | B4: Antwerpen | C4: Botellón | D4: Waalsekaai 45A, 2000 Antwerpen | E4: Nee | F4: Ja | G4: Geen specialty koffiebar; één review is negatief over de koffie. | H4: link
A5: Antwerpen | B5: Antwerpen | C5: Caffènation | D5: Mechelsesteenweg 16 | E5: Ja | F5: ? | G5: Elle: twee verdiepingen, veel werkplek; gratis wifi. Ter plaatse: stopcontacten, fietsenrek? | H5: link
A6: Antwerpen | B6: Antwerpen | C6: Caffènation Roastery | D6: Lamorinièrestraat 161 | E6: Ja | F6: ? | G6: Wifi, stopcontacten, coworking-vriendelijk volgens nomadensite; wel lawaaierig (branderij). Ter plaatse: fietsenrek? | H6: link
A7: Antwerpen | B7: Antwerpen | C7: Café Canelé | D7: Kronenburgstraat 41D, 2000 Antwerpen | E7: Ja | F7: Nee | H7: link
A8: Antwerpen | B8: Antwerpen | C8: Fuel South | D8: Waalsekaai 27, 2000 Antwerpen | E8: Nee | F8: Nee | G8: Niet zeker. Eerder een healthy restaurant dan een koffiebar. Wielercafé stond niet ingevuld: geen bron, dus 'nee'. | H8: link
A9: Antwerpen | B9: Antwerpen | C9: Funk Berchem | D9: Belpairestraat 10, 2600 Berchem | E9: Ja | F9: Nee | G9: Huisnummer 10 of 20: ter plaatse checken. | H9: link
A10: Antwerpen | B10: Antwerpen | C10: Funk Zuid | D10: Kronenburgstraat 41A, 2000 Antwerpen | E10: Ja | F10: Ja | H10: link
A11: Antwerpen | B11: Antwerpen | C11: Koffie Dealers | D11: Paardenmarkt 117 | E11: Ja | F11: ? | G11: Goede wifi, veel stopcontacten, werktafels (75% laptopvriendelijk). Ter plaatse: weekendbeleid, fietsenrek? | H11: link
A12: Antwerpen | B12: Antwerpen | C12: Kolonel & Reede | D12: Ankerrui 15 | E12: ? | F12: ? | G12: Ruim, grote ramen; vanaf 16u wijnbar. Geen info wifi/laptops. Ter plaatse: wifi, stopcontacten, fietsenrek? | H12: link
A13: Antwerpen | B13: Antwerpen | C13: Kolonel Coffee | D13: Montignystraat 51 | E13: Ja | F13: ? | G13: Elle: laptopvriendelijk, bar aan het raam, veel daglicht. Ter plaatse: stopcontacten, fietsenrek? | H13: link
A14: Antwerpen | B14: Antwerpen | C14: Nives | D14: Harmoniestraat 25B | E14: Ja | F14: ? | G14: Wifi, werken mag, ruim interieur; ELLE-tip om te telewerken. Terras aan Harmoniepark. Ter plaatse: stopcontacten, fietsenrek? | H14: link
A15: Antwerpen | B15: Antwerpen | C15: Nordica 31 | D15: Belegstraat 31, 2018 Antwerpen | E15: Nee | F15: Ja | H15: link
A16: Antwerpen | B16: Antwerpen | C16: Normo | D16: Minderbroedersrui 30 | E16: ? | F16: ? | G16: Werkspotgids: kleine marmeren tafeltjes, eerder voor kort bezoek. Wifi/stopcontacten onbekend. Ter plaatse: wifi, fietsenrek? | H16: link
A17: Antwerpen | B17: Antwerpen | C17: Polly | D17: Cuperusstraat 1, 2018 Antwerpen | E17: Ja | F17: Ja | H17: link
A18: Antwerpen | B18: Antwerpen | C18: Rush Rush | D18: Lange Altaarstraat 29 | E18: Ja | F18: ? | G18: Gratis wifi, laptopvriendelijk (ECT), rustig volgens ELLE-telewerklijst. Ter plaatse: stopcontacten, fietsenrek? | H18: link
A19: Antwerpen | B19: Antwerpen | C19: Tartoer | D19: Korte Koepoortstraat 2 | E19: ? | F19: ? | G19: Stabiele wifi, matig stopcontacten, weinig ruimte (58% laptopvriendelijk). Ter plaatse: laptopbeleid, fietsenrek? | H19: link
A20: Antwerpen | B20: Antwerpen | C20: Tinsel | D20: Sint-Paulusplaats 30, 2000 Antwerpen | E20: Ja | F20: Nee | G20: Druk brunchadres; laptop komt uit jouw notitie. | H20: link
A21: Antwerpen | B21: Antwerpen | C21: Vitesse Coffee & Cycling | D21: Provinciestraat 82 | E21: Ja | F21: Ja | G21: Wifi, veel stopcontacten, grote tafels; wielerdecor en koersfietsen. Ter plaatse: fietsenrek? | H21: link
A22: Gent | B22: Gent | C22: Bar Bidon | D22: Bisdomkaai 25 | E22: Ja | F22: Ja | G22: Bidon Coffee & Bicycle: wielerthema; gratis wifi, stopcontacten, ruim. Ter plaatse: fietsenrek, drukte weekend? | H22: link
A23: Gent | B23: Gent | C23: Café Labath | D23: Oude Houtlei 1 | E23: Ja | F23: ? | G23: Gratis wifi (code vragen), als laptopvriendelijk vermeld. Ter plaatse: stopcontacten, fietsenrek? | H23: link
A24: Gent | B24: Gent | C24: Full Circle Coffee | D24: Zuidstationstraat 5 | E24: Ja | F24: ? | G24: Gratis wifi, 'good for laptop', binnen en buiten zitten (bron aggregator); alleen kaart. Ter plaatse: stopcontacten, fietsenrek? | H24: link
A25: Gent | B25: Gent | C25: Goya Coffee | D25: Verlorenkost 5 | E25: Ja | F25: ? | G25: Wifi, 'perfecte plek om te werken' volgens Koffietje. Ter plaatse: stopcontacten, fietsenrek? | H25: link
A26: Gent | B26: Gent | C26: Koffeine | D26: Lange Kruisstraat 6 | E26: ? | F26: ? | G26: Kleine zaak, geen info over wifi of laptops gevonden. Ter plaatse: wifi, stopcontacten, plaats? | H26: link
A27: Gent | B27: Gent | C27: OR Coffee | D27: Sint-Pietersnieuwstraat 126A | E27: Ja | F27: ? | G27: Wifi, 'perfecte plek om te werken', studenten met laptops. Ter plaatse: stopcontacten, fietsenrek? | H27: link
A28: Gent | B28: Gent | C28: OR Espresso Bar | D28: Dok-Noord 7 | E28: ? | F28: ? | G28: Volgens Wanderlog definitief gesloten; ook niet meer op OR-site. Verifiëren en eventueel verwijderen. | H28: link
A29: Gent | B29: Gent | C29: Take Five Espressobar | D29: Voldersstraat 10 | E29: Ja | F29: ? | G29: Wifi, laptops toegestaan, tafelbediening; klein en druk. Ter plaatse: stopcontacten, fietsenstalling in voetgangerszone. | H29: link
... A33: Brussel | B33: Brussel | C33: Aksum | D33: Koninginnegalerij | E33: Ja | F33: ? | G33: Laptopvriendelijk volgens gids: gratis wifi, stopcontacten; klein zaakje in galerij. Ter plaatse: plaats, fietsparkeren? | H33: link
A34: Brussel | B34: Brussel | C34: Barkboy | D34: Onderrichtsstraat 20, 1000 Brussel | E34: Ja | F34: Nee | H34: link
A35: Brussel | B35: Brussel | C35: Batch | D35: Waterloosesteenweg 559, 1050 Elsene | E35: Nee | F35: Nee | G35: Eerder restaurant; ma dicht, di alleen 's avonds. | H35: link
A36: Brussel | B36: Brussel | C36: Belga & Co | D36: Baljuwstraat, Elsene | E36: Ja | F36: ? | G36: Freelancers werken er uren met laptop; tuin. Ter plaatse: stopcontacten, fietsenrek? | H36: link
A37: Brussel | B37: Brussel | C37: Belga & Co Boniface | D37: Ernest Solvaystraat 12, 1050 Elsene | E37: Ja | F37: Nee | G37: Andere zaak dan Belga & Co aan de Baljuwstraat. Goede wifi, maar laptops niet welkom als het druk is. | H37: link
A38: Brussel | B38: Brussel | C38: Bouche | D38: Naamsestraat 4, 1000 Brussel | E38: Ja | F38: Nee | H38: link
A39: Brussel | B39: Brussel | C39: Bouche Saint-Géry | D39: Sint-Goriks | E39: ? | F39: ? | G39: Bouche: laptops enkel weekdagen, ±4 werkplekken (review Namenstraat-adres). Ter plaatse: geldt dit ook Sint-Goriks? | H39: link
A40: Brussel | B40: Brussel | C40: Buddy Buddy | D40: Lakenweversstraat 10, 1050 Elsene | E40: Nee | F40: Nee | G40: Er is gratis wifi; jij zei nee. | H40: link
A41: Brussel | B41: Brussel | C41: Café de la Presse | D41: Kardinaal Mercierstraat 41, 1000 Brussel | E41: Ja | F41: Nee | H41: link
A42: Brussel | B42: Brussel | C42: Cyclovia | D42: Waterloosesteenweg 521, Elsene | E42: ? | F42: Ja | G42: Koersfietsenmaker met koffiebar; geen info over wifi of zitplaatsen gevonden. Ter plaatse: wifi, tafels? | H42: link
A43: Brussel | B43: Brussel | C43: Drache | D43: Brandhoutkaai 11, 1000 Brussel | E43: Nee | F43: Nee | G43: Een bron noemt het geschikt voor een laptoppauze; jij zei nee. Pas aan als je wil. | H43: link
...

Sheet Overzicht
A1: Regio | B1: Bars | C1: 💻 PC: Ja | D1: 💻 PC: ? | E1: 🚴 Cycling: Ja | F1: 🚴 Cycling: ? | G1: Al bezocht
A2: Antwerpen | B2: =COUNTIF(Bars!$A$2:$A$103,A2) -> 20 | C2: =COUNTIFS(Bars!$A$2:$A$103,A2,Bars!$E$2:$E$103,"Ja") -> 13 | D2: =COUNTIFS(Bars!$A$2:$A$103,A2,Bars!$E$2:$E$103,"?") -> 4 | E2: =COUNTIFS(Bars!$A$2:$A$103,A2,Bars!$F$2:$F$103,"Ja") -> 5 | F2: =COUNTIFS(Bars!$A$2:$A$103,A2,Bars!$F$2:$F$103,"?") -> 11 | G2: =COUNTIFS(Bars!$A$2:$A$103,A2,Bars!$I$2:$I$103,"<>") -> 0
A3: Gent | B3: =COUNTIF(Bars!$A$2:$A$103,A3) -> 11 | C3: =COUNTIFS(Bars!$A$2:$A$103,A3,Bars!$E$2:$E$103,"Ja") -> 8 | D3: =COUNTIFS(Bars!$A$2:$A$103,A3,Bars!$E$2:$E$103,"?") -> 2 | E3: =COUNTIFS(Bars!$A$2:$A$103,A3,Bars!$F$2:$F$103,"Ja") -> 1 | F3: =COUNTIFS(Bars!$A$2:$A$103,A3,Bars!$F$2:$F$103,"?") -> 10 | G3: =COUNTIFS(Bars!$A$2:$A$103,A3,Bars!$I$2:$I$103,"<>") -> 0
A4: Brussel | B4: =COUNTIF(Bars!$A$2:$A$103,A4) -> 28 | C4: =COUNTIFS(Bars!$A$2:$A$103,A4,Bars!$E$2:$E$103,"Ja") -> 13 | D4: =COUNTIFS(Bars!$A$2:$A$103,A4,Bars!$E$2:$E$103,"?") -> 6 | E4: =COUNTIFS(Bars!$A$2:$A$103,A4,Bars!$F$2:$F$103,"Ja") -> 5 | F4: =COUNTIFS(Bars!$A$2:$A$103,A4,Bars!$F$2:$F$103,"?") -> 6 | G4: =COUNTIFS(Bars!$A$2:$A$103,A4,Bars!$I$2:$I$103,"<>") -> 0
A5: Leuven | B5: =COUNTIF(Bars!$A$2:$A$103,A5) -> 5 | C5: =COUNTIFS(Bars!$A$2:$A$103,A5,Bars!$E$2:$E$103,"Ja") -> 3 | D5: =COUNTIFS(Bars!$A$2:$A$103,A5,Bars!$E$2:$E$103,"?") -> 2 | E5: =COUNTIFS(Bars!$A$2:$A$103,A5,Bars!$F$2:$F$103,"Ja") -> 1 | F5: =COUNTIFS(Bars!$A$2:$A$103,A5,Bars!$F$2:$F$103,"?") -> 4 | G5: =COUNTIFS(Bars!$A$2:$A$103,A5,Bars!$I$2:$I$103,"<>") -> 0
A6: Knokke | B6: =COUNTIF(Bars!$A$2:$A$103,A6) -> 5 | C6: =COUNTIFS(Bars!$A$2:$A$103,A6,Bars!$E$2:$E$103,"Ja") -> 0 | D6: =COUNTIFS(Bars!$A$2:$A$103,A6,Bars!$E$2:$E$103,"?") -> 5 | E6: =COUNTIFS(Bars!$A$2:$A$103,A6,Bars!$F$2:$F$103,"Ja") -> 0 | F6: =COUNTIFS(Bars!$A$2:$A$103,A6,Bars!$F$2:$F$103,"?") -> 5 | G6: =COUNTIFS(Bars!$A$2:$A$103,A6,Bars!$I$2:$I$103,"<>") -> 0
A7: Rest van België | B7: =COUNTIF(Bars!$A$2:$A$103,A7) -> 26 | C7: =COUNTIFS(Bars!$A$2:$A$103,A7,Bars!$E$2:$E$103,"Ja") -> 13 | D7: =COUNTIFS(Bars!$A$2:$A$103,A7,Bars!$E$2:$E$103,"?") -> 9 | E7: =COUNTIFS(Bars!$A$2:$A$103,A7,Bars!$F$2:$F$103,"Ja") -> 24 | F7: =COUNTIFS(Bars!$A$2:$A$103,A7,Bars!$F$2:$F$103,"?") -> 0 | G7: =COUNTIFS(Bars!$A$2:$A$103,A7,Bars!$I$2:$I$103,"<>") -> 1
A8: Costa Blanca (ES) | B8: =COUNTIF(Bars!$A$2:$A$103,A8) -> 7 | C8: =COUNTIFS(Bars!$A$2:$A$103,A8,Bars!$E$2:$E$103,"Ja") -> 6 | D8: =COUNTIFS(Bars!$A$2:$A$103,A8,Bars!$E$2:$E$103,"?") -> 0 | E8: =COUNTIFS(Bars!$A$2:$A$103,A8,Bars!$F$2:$F$103,"Ja") -> 6 | F8: =COUNTIFS(Bars!$A$2:$A$103,A8,Bars!$F$2:$F$103,"?") -> 0 | G8: =COUNTIFS(Bars!$A$2:$A$103,A8,Bars!$I$2:$I$103,"<>") -> 0
A9: Totaal | B9: =SUM(B2:B8) -> 102 | C9: =SUM(C2:C8) -> 56 | D9: =SUM(D2:D8) -> 28 | E9: =SUM(E2:E8) -> 42 | F9: =SUM(F2:F8) -> 36 | G9: =SUM(G2:G8) -> 1
